<!--
robotiq-3f-gripper_articulated_macro(prefix)

Creates an articulated robotiq-3f-gripper hand with the passed in prefix.  If there
is only one hand in the urdf then an empty prefix can be used "".  If
there are multiple hands then a prefix followed by an "_" is needed.

-->
<robot xmlns:xacro="http://ros.org/wiki/xacro">
        <xacro:property name="s1" value="0.85" />
        <xacro:property name="e1" value="40" />
        <xacro:include filename="$(find robotiq_3f_gripper_visualization)/cfg/robotiq-3f-gripper_finger_articulated_macro.xacro" />
        <xacro:macro name="robotiq-3f-gripper_articulated" params="prefix *origin reflect parent">
        <xacro:robotiq-3f-gripper_finger_articulated prefix="${prefix}finger_1_"/>
        <xacro:robotiq-3f-gripper_finger_articulated prefix="${prefix}finger_2_"/>
        <xacro:robotiq-3f-gripper_finger_articulated prefix="${prefix}finger_middle_"/>
		<!-- link list -->
		<link name="${prefix}palm">
			<visual>
				<geometry>
                                        <mesh filename="package://robotiq_3f_gripper_visualization/meshes/robotiq-3f-gripper_articulated/visual/palm.STL" />
				</geometry>
				<material name="gray">
					<color rgba="0.2 0.2 0.2 1"/>
				</material>
			</visual>
			<collision>
				<geometry>
                                        <mesh filename="package://robotiq_3f_gripper_visualization/meshes/robotiq-3f-gripper_articulated/collision/palm.STL" />
				</geometry>
				<material name="yellow">
					<color rgba="0 1 1 1"/>
				</material>
			</collision>
		</link>

	    <gazebo reference="${prefix}palm">
      		<mu1>1.1</mu1>
      		<mu2>1.1</mu2>
    	</gazebo>
	      
        <inertial>
            <origin xyz="0 0 0" rpy="0 0 0"/>
            <mass value="1.3"/>
            <inertia ixx="0.006012" ixy="0.000079" ixz="-0.00024" iyy="0.012892" iyz="0" izz="0.002435" />
        </inertial>
		<!-- end of link list -->
		<!-- joint list -->

		<joint name="${prefix}palm_finger_1_joint" type="revolute">
			<parent link="${prefix}palm"/>
			<child link="${prefix}finger_1_link_0"/>
			<axis xyz="0 1 0"/>
			<origin xyz="-0.0455 0.0214 0.036" rpy="0 3.1416 -1.57"/>
                        <limit lower="-0.1784" upper="0.192" effort="100" velocity="${s1}"/>
		</joint>
		<joint name="${prefix}palm_finger_2_joint" type="revolute">
			<parent link="${prefix}palm"/>
			<child link="${prefix}finger_2_link_0"/>
			<axis xyz="0 1 0"/>
			<origin xyz="-0.0455 0.0214 -0.036" rpy="0 3.1416 -1.57"/>
                        <limit lower="-0.192" upper="0.1784" effort="100" velocity="${s1}"/>
		</joint>
		<joint name="${prefix}palm_finger_middle_joint" type="fixed">
			<parent link="${prefix}palm"/>
			<child link="${prefix}finger_middle_link_0"/>
			<axis xyz="0 0 1"/>
			<origin xyz="0.0455 0.0214 0" rpy="0 0 1.57"/>
		</joint>
		<joint name="${prefix}robotiq_hand_joint" type="fixed">
      		<insert_block name="origin"/>
      		<parent link="${parent}"/>
      		<child link="${prefix}palm"/>
    	</joint>

    <transmission name="${prefix}palm_finger_1_trans">
      <type>transmission_interface/SimpleTransmission</type>
      <joint name="${prefix}palm_finger_1_joint">
        <hardwareInterface>hardware_interface/EffortJointInterface</hardwareInterface>
      </joint>
      <actuator name="${prefix}palm_finger_1_motor">
        <mechanicalReduction>1</mechanicalReduction>
      </actuator>
    </transmission>

    <transmission name="${prefix}palm_finger_2_trans">
      <type>transmission_interface/SimpleTransmission</type>
      <joint name="${prefix}palm_finger_2_joint">
        <hardwareInterface>hardware_interface/EffortJointInterface</hardwareInterface>
      </joint>
      <actuator name="${prefix}palm_finger_2_motor">
        <mechanicalReduction>1</mechanicalReduction>
      </actuator>
    </transmission>


		<!-- end of joint list -->
	</xacro:macro>
</robot>
